version: '3.8'

services:
  app:
    build:
     context: .
     dockerfile: Dockerfile
    ports:
      - "8000:8000"
    env_file:
      - .env
    environment:
      - PYTHONUNBUFFERED=1
      - POSTGRES_PASSWORD=${POSTGRES_PASSWORD?Variable not set}
      - POSTGRES_USER=${POSTGRES_USER?Variable not set}
      - POSTGRES_DB=${POSTGRES_DB?Variable not set}
      - POSTGRES_HOST=${POSTGRES_HOST?Variable not set}
      - POSTGRES_PORT=${POSTGRES_PORT?Variable not set}
    depends_on:
      db:
        condition: service_healthy
    networks:
      - app-network

  db:
    image: postgres:16.4-alpine
    env_file:
      - .env
    environment:
      - POSTGRES_PASSWORD=${POSTGRES_PASSWORD?Variable not set}
      - POSTGRES_USER=${POSTGRES_USER?Variable not set}
      - POSTGRES_DB=${POSTGRES_DB?Variable not set}
    expose:
      - "5432"
    volumes:
      - postgres-data:/var/lib/postgresql/data
      - ./sql/criacao.sql:/docker-entrypoint-initdb.d/001_criacao.sql
      - ./sql/insercao.sql:/docker-entrypoint-initdb.d/002_insercao.sql
    networks:
      - app-network
    healthcheck:
      test: ["CMD-SHELL", "pg_isready -U $POSTGRES_USER -d $POSTGRES_DB"]
      interval: 1s
      timeout: 5s
      retries: 5

networks:
  app-network:
    driver: bridge

volumes:
  postgres-data: